<?xml version="1.0"?>
<robot name="simple_humanoid">

    <!-- Base Link (Torso) -->
    <link name="base_link">
        <visual>
            <geometry>
                <box size="0.2 0.1 0.4"/>
            </geometry>
            <material name="gray">
                <color rgba="0.5 0.5 0.5 1"/>
            </material>
        </visual>
        <collision>
            <geometry>
                <box size="0.2 0.1 0.4"/>
            </geometry>
        </collision>
        <inertial>
            <mass value="10.0"/>
            <origin xyz="0 0 0"/>
            <inertia ixx="1.0" ixy="0" ixz="0" iyy="1.0" iyz="0" izz="1.0"/>
        </inertial>
    </link>

    <!-- Head Link -->
    <link name="head_link">
        <visual>
            <geometry>
                <sphere radius="0.1"/>
            </geometry>
            <material name="red">
                <color rgba="0.8 0 0 1"/>
            </material>
        </visual>
        <collision>
            <geometry>
                <sphere radius="0.1"/>
            </geometry>
        </collision>
        <inertial>
            <mass value="1.0"/>
            <origin xyz="0 0 0"/>
            <inertia ixx="0.1" ixy="0" ixz="0" iyy="0.1" iyz="0" izz="0.1"/>
        </inertial>
    </link>

    <!-- Joint: Base to Head -->
    <joint name="base_to_head_joint" type="revolute">
        <origin xyz="0 0 0.25" rpy="0 0 0"/> <!-- Position relative to parent link's origin -->
        <parent link="base_link"/>
        <child link="head_link"/>
        <axis xyz="0 0 1"/> <!-- Yaw rotation -->
        <limit lower="-1.57" upper="1.57" velocity="0.5" effort="100"/>
    </joint>

    <!-- Right Arm Link -->
    <link name="right_arm_link">
        <visual>
            <geometry>
                <cylinder radius="0.03" length="0.3"/>
            </geometry>
            <material name="green">
                <color rgba="0 0.8 0 1"/>
            </material>
        </visual>
        <collision>
            <geometry>
                <cylinder radius="0.03" length="0.3"/>
            </geometry>
        </collision>
        <inertial>
            <mass value="0.5"/>
            <origin xyz="0 0 0.15"/>
            <inertia ixx="0.01" ixy="0" ixz="0" iyy="0.01" iyz="0" izz="0.01"/>
        </inertial>
    </link>

    <!-- Joint: Base to Right Arm -->
    <joint name="base_to_right_arm_joint" type="revolute">
        <origin xyz="-0.12 0 0.15" rpy="0 0 0"/>
        <parent link="base_link"/>
        <child link="right_arm_link"/>
        <axis xyz="0 1 0"/> <!-- Pitch rotation -->
        <limit lower="-1.57" upper="1.57" velocity="0.5" effort="100"/>
    </joint>

    <!-- Left Arm Link (similar to right arm) -->
    <link name="left_arm_link">
        <visual>
            <geometry>
                <cylinder radius="0.03" length="0.3"/>
            </geometry>
            <material name="green">
                <color rgba="0 0.8 0 1"/>
            </material>
        </visual>
        <collision>
            <geometry>
                <cylinder radius="0.03" length="0.3"/>
            </geometry>
        </collision>
        <inertial>
            <mass value="0.5"/>
            <origin xyz="0 0 0.15"/>
            <inertia ixx="0.01" ixy="0" ixz="0" iyy="0.01" iyz="0" izz="0.01"/>
        </inertial>
    </link>

    <!-- Joint: Base to Left Arm -->
    <joint name="base_to_left_arm_joint" type="revolute">
        <origin xyz="0.12 0 0.15" rpy="0 0 0"/>
        <parent link="base_link"/>
        <child link="left_arm_link"/>
        <axis xyz="0 1 0"/> <!-- Pitch rotation -->
        <limit lower="-1.57" upper="1.57" velocity="0.5" effort="100"/>
    </joint>

</robot>